Workbook
Name _Hlk101434402: Sheet1!$A$38

Sheet Sheet1
A1: PRETEST | B1: kode | C1: PRAKOM | D1: //PRAKOMAHLI_PRETEST
A2: Menurut Mayer, multimedia akan lebih maksimal jika menggunakan gabungan dari grafik dan narasi, dibandingkan dengan hanya penggunaan grafik saja atau narasi saja. Prinsip ini disebut | D2: =CONCATENATE("::",$A$1,"_",$C$1,"_") -> ::PRETEST_PRAKOM_ | E2: 001 | F2: :: | G2: [moodle] | H2: [html] | I2: =CONCATENATE(D2,E2,F2,H2,A2," \:{") -> ::PRETEST_PRAKOM_001::[html]Menurut Mayer, multimedia akan lebih maksimal jika menggunakan gabungan dari grafik dan narasi, dibandingkan dengan hanya penggunaan grafik saja atau narasi saja. Prinsip ini disebut \:{ | J2: =CONCATENATE(I2,I3,I4,I5,I6) -> ::PRETEST_PRAKOM_001::[html]Menurut Mayer, multimedia akan lebih maksimal jika menggunakan gabungan dari grafik dan narasi, dibandingkan dengan hanya penggunaan grafik saja atau narasi saja. Prinsip ini disebut \:{=[moodle]Redundansi ~[moodle]Kedekatan sementara ~[moodle]Penandanaan ~[moodle]Koherensi}
A3: Redundansi | B3: 1 | I3: =IF(B3=1,CONCATENATE("=",G2,A3," "),CONCATENATE("~",G2,A3," ")) -> =[moodle]Redundansi
A4: Kedekatan sementara | B4: 0 | I4: =IF(B4=1,CONCATENATE("=",G2,A4," "),CONCATENATE("~",G2,A4," ")) -> ~[moodle]Kedekatan sementara
A5: Penandanaan | B5: 0 | I5: =IF(B5=1,CONCATENATE("=",G2,A5," "),CONCATENATE("~",G2,A5," ")) -> ~[moodle]Penandanaan
A6: Koherensi | B6: 0 | I6: =IF(B6=1,CONCATENATE("=",G2,A6,"}"),CONCATENATE("~",G2,A6,"}")) -> ~[moodle]Koherensi}
A7: Peta tematik disebut juga dengan | D7: =CONCATENATE("::",$A$1,"_",$C$1,"_") -> ::PRETEST_PRAKOM_ | E7: 002 | F7: :: | G7: [moodle] | H7: [html] | I7: =CONCATENATE(D7,E7,F7,H7,A7," \:{") -> ::PRETEST_PRAKOM_002::[html]Peta tematik disebut juga dengan \:{ | J7: =CONCATENATE(I7,I8,I9,I10,I11) -> ::PRETEST_PRAKOM_002::[html]Peta tematik disebut juga dengan \:{~[moodle]Peta Umum =[moodle]Peta Khusus ~[moodle]Peta Topografi ~[moodle]Peta Dunia}
A8: Peta Umum | B8: 0 | I8: =IF(B8=1,CONCATENATE("=",$G$7,A8," "),CONCATENATE("~",$G$7,A8," ")) -> ~[moodle]Peta Umum
A9: Peta Khusus | B9: 1 | I9: =IF(B9=1,CONCATENATE("=",$G$7,A9," "),CONCATENATE("~",$G$7,A9," ")) -> =[moodle]Peta Khusus
A10: Peta Topografi | B10: 0 | I10: =IF(B10=1,CONCATENATE("=",$G$7,A10," "),CONCATENATE("~",$G$7,A10," ")) -> ~[moodle]Peta Topografi
A11: Peta Dunia | B11: 0 | I11: =IF(B11=1,CONCATENATE("=",$G$7,A11,"}"),CONCATENATE("~",$G$7,A11,"}")) -> ~[moodle]Peta Dunia}
A12: Konten yang merupakan kombinasi dari teks, suara, gambar, animasi, dan video yang dimanipulasi secara digital disebut | D12: =CONCATENATE("::",$A$1,"_",$C$1,"_") -> ::PRETEST_PRAKOM_ | E12: 003 | F12: :: | G12: [moodle] | H12: [html] | I12: =CONCATENATE(D12,E12,F12,H12,A12," \:{") -> ::PRETEST_PRAKOM_003::[html]Konten yang merupakan kombinasi dari teks, suara, gambar, animasi, dan video yang dimanipulasi secara digital disebut \:{ | J12: =CONCATENATE(I12,I13,I14,I15,I16) -> ::PRETEST_PRAKOM_003::[html]Konten yang merupakan kombinasi dari teks, suara, gambar, animasi, dan video yang dimanipulasi secara digital disebut \:{~[moodle]Adsense ~[moodle]Multilevel =[moodle]Multimedia ~[moodle]Flowchart}
A13: Adsense | B13: 0 | I13: =IF(B13=1,CONCATENATE("=",$G$7,A13," "),CONCATENATE("~",$G$7,A13," ")) -> ~[moodle]Adsense
A14: Multilevel | B14: 0 | I14: =IF(B14=1,CONCATENATE("=",$G$7,A14," "),CONCATENATE("~",$G$7,A14," ")) -> ~[moodle]Multilevel
A15: Multimedia | B15: 1 | I15: =IF(B15=1,CONCATENATE("=",$G$7,A15," "),CONCATENATE("~",$G$7,A15," ")) -> =[moodle]Multimedia
A16: Flowchart | B16: 0 | I16: =IF(B16=1,CONCATENATE("=",$G$7,A16,"}"),CONCATENATE("~",$G$7,A16,"}")) -> ~[moodle]Flowchart}
A17: Pengujian aplikasi yang dilakukan oleh pengguna menggunakan perangkat masing-masing disebut juga dengan | D17: =CONCATENATE("::",$A$1,"_",$C$1,"_") -> ::PRETEST_PRAKOM_ | E17: 004 | F17: :: | G17: [moodle] | H17: [html] | I17: =CONCATENATE(D17,E17,F17,H17,A17," \:{") -> ::PRETEST_PRAKOM_004::[html]Pengujian aplikasi yang dilakukan oleh pengguna menggunakan perangkat masing-masing disebut juga dengan \:{ | J17: =CONCATENATE(I18,I19,I20,I21) -> =[moodle]Pengujian aplikasi yang dilakukan oleh pengguna menggunakan perangkat masing-masing disebut juga dengan ~[moodle]Integration Test ~[moodle]Destructive Test ~[moodle]Latency Test}
A18: User Acceptance | B18: 1 | I18: =IF(B18=1,CONCATENATE("=",$G$7,A17," "),CONCATENATE("~",$G$7,A17," ")) -> =[moodle]Pengujian aplikasi yang dilakukan oleh pengguna menggunakan perangkat masing-masing disebut juga dengan
A19: Integration Test | B19: 0 | I19: =IF(B19=1,CONCATENATE("=",$G$7,A19," "),CONCATENATE("~",$G$7,A19," ")) -> ~[moodle]Integration Test
A20: Destructive Test | B20: 0 | I20: =IF(B20=1,CONCATENATE("=",$G$7,A20," "),CONCATENATE("~",$G$7,A20," ")) -> ~[moodle]Destructive Test
A21: Latency Test | B21: 0 | I21: =IF(B21=1,CONCATENATE("=",$G$7,A21,"}"),CONCATENATE("~",$G$7,A21,"}")) -> ~[moodle]Latency Test}
A22: Keseluruhan inisiatif TI yang terdiri dari visi, misi, tujuan, prinsip, dan taktik yang berkaitan dengan pemanfaatan TI dalam organisasi tertuang di dalam | D22: =CONCATENATE("::",$A$1,"_",$C$1,"_") -> ::PRETEST_PRAKOM_ | E22: 005 | F22: :: | G22: [moodle] | H22: [html] | I22: =CONCATENATE(D22,E22,F22,H22,A22," \:{") -> ::PRETEST_PRAKOM_005::[html]Keseluruhan inisiatif TI yang terdiri dari visi, misi, tujuan, prinsip, dan taktik yang berkaitan dengan pemanfaatan TI dalam organisasi tertuang di dalam \:{ | J22: =CONCATENATE(I22,I23,I24,I25,I26) -> ::PRETEST_PRAKOM_005::[html]Keseluruhan inisiatif TI yang terdiri dari visi, misi, tujuan, prinsip, dan taktik yang berkaitan dengan pemanfaatan TI dalam organisasi tertuang di dalam \:{~[moodle]Kebijakan TI =[moodle]Strategi TI ~[moodle]Tata Kelola TI ~[moodle]Roadmap TI}
A23: Kebijakan TI | B23: 0 | I23: =IF(B23=1,CONCATENATE("=",$G$7,A23," "),CONCATENATE("~",$G$7,A23," ")) -> ~[moodle]Kebijakan TI
A24: Strategi TI | B24: 1 | I24: =IF(B24=1,CONCATENATE("=",$G$7,A24," "),CONCATENATE("~",$G$7,A24," ")) -> =[moodle]Strategi TI
A25: Tata Kelola TI | B25: 0 | I25: =IF(B25=1,CONCATENATE("=",$G$7,A25," "),CONCATENATE("~",$G$7,A25," ")) -> ~[moodle]Tata Kelola TI
A26: Roadmap TI | B26: 0 | I26: =IF(B26=1,CONCATENATE("=",$G$7,A26,"}"),CONCATENATE("~",$G$7,A26,"}")) -> ~[moodle]Roadmap TI}
A27: Suatu strategi yang spesifik untuk melaksanakan suatu rencana TI yang telah disusun agar dapat berjalan dan diimplementasikan sesuai dengan target yang diinginkan dengan menggunakan sumber daya seefektif dan seefisien mungkin | D27: =CONCATENATE("::",$A$1,"_",$C$1,"_") -> ::PRETEST_PRAKOM_ | E27: 006 | F27: :: | G27: [moodle] | H27: [html] | I27: =CONCATENATE(D27,E27,F27,H27,A27," \:{") -> ::PRETEST_PRAKOM_006::[html]Suatu strategi yang spesifik untuk melaksanakan suatu rencana TI yang telah disusun agar dapat berjalan dan diimplementasikan sesuai dengan target yang diinginkan dengan menggunakan sumber daya seefektif dan seefisien mungkin \:{ | J27: =CONCATENATE(I27,I28,I29,I30,I31) -> ::PRETEST_PRAKOM_006::[html]Suatu strategi yang spesifik untuk melaksanakan suatu rencana TI yang telah disusun agar dapat berjalan dan diimplementasikan sesuai dengan target yang diinginkan dengan menggunakan sumber daya seefektif dan seefisien mungkin \:{~[moodle]Strategi TI ~[moodle]Strategi Layanan TI ~[moodle]Strategi Pembiayaan TI =[moodle]Strategi Operasional TI}
A28: Strategi TI | B28: 0 | I28: =IF(B28=1,CONCATENATE("=",$G$7,A28," "),CONCATENATE("~",$G$7,A28," ")) -> ~[moodle]Strategi TI
A29: Strategi Layanan TI | B29: 0 | I29: =IF(B29=1,CONCATENATE("=",$G$7,A29," "),CONCATENATE("~",$G$7,A29," ")) -> ~[moodle]Strategi Layanan TI
A30: Strategi Pembiayaan TI | B30: 0 | I30: =IF(B30=1,CONCATENATE("=",$G$7,A30," "),CONCATENATE("~",$G$7,A30," ")) -> ~[moodle]Strategi Pembiayaan TI
A31: Strategi Operasional TI | B31: 1 | I31: =IF(B31=1,CONCATENATE("=",$G$7,A31,"}"),CONCATENATE("~",$G$7,A31,"}")) -> =[moodle]Strategi Operasional TI}
A32: Berikut ini yang bukan manfaat yang bisa didapatkan dari pengembangan Enterprise Architecture adalah | D32: =CONCATENATE("::",$A$1,"_",$C$1,"_") -> ::PRETEST_PRAKOM_ | E32: 007 | F32: :: | G32: [moodle] | H32: [html] | I32: =CONCATENATE(D32,E32,F32,H32,A32," \:{") -> ::PRETEST_PRAKOM_007::[html]Berikut ini yang bukan manfaat yang bisa didapatkan dari pengembangan Enterprise Architecture adalah \:{ | J32: =CONCATENATE(I32,I33,I34,I35,I36) -> ::PRETEST_PRAKOM_007::[html]Berikut ini yang bukan manfaat yang bisa didapatkan dari pengembangan Enterprise Architecture adalah \:{~[moodle]Mempunyai portofolio aplikasi dan teknologi yang dapat digunakan untuk pengelolaan TIK ~[moodle]Dapat dijadikan dasar pengembangan manajemen risiko =[moodle]Mempunyai informasi kebutuhan pengguna untuk dasar pengembangan aplikasi ~[moodle]Dasar perencanaan strategi dan pengambilan kebijakan}
A33: Mempunyai portofolio aplikasi dan teknologi yang dapat digunakan untuk pengelolaan TIK | B33: 0 | I33: =IF(B33=1,CONCATENATE("=",$G$7,A33," "),CONCATENATE("~",$G$7,A33," ")) -> ~[moodle]Mempunyai portofolio aplikasi dan teknologi yang dapat digunakan untuk pengelolaan TIK
A34: Dapat dijadikan dasar pengembangan manajemen risiko | B34: 0 | I34: =IF(B34=1,CONCATENATE("=",$G$7,A34," "),CONCATENATE("~",$G$7,A34," ")) -> ~[moodle]Dapat dijadikan dasar pengembangan manajemen risiko
A35: Mempunyai informasi kebutuhan pengguna untuk dasar pengembangan aplikasi | B35: 1 | I35: =IF(B35=1,CONCATENATE("=",$G$7,A35," "),CONCATENATE("~",$G$7,A35," ")) -> =[moodle]Mempunyai informasi kebutuhan pengguna untuk dasar pengembangan aplikasi
A36: Dasar perencanaan strategi dan pengambilan kebijakan | B36: 0 | I36: =IF(B36=1,CONCATENATE("=",$G$7,A36,"}"),CONCATENATE("~",$G$7,A36,"}")) -> ~[moodle]Dasar perencanaan strategi dan pengambilan kebijakan}
A37: Prinsip utama yang harus dipegang dalam penyusunan Strategi TI adalah | D37: =CONCATENATE("::",$A$1,"_",$C$1,"_") -> ::PRETEST_PRAKOM_ | E37: 008 | F37: :: | G37: [moodle] | H37: [html] | I37: =CONCATENATE(D37,E37,F37,H37,A37," \:{") -> ::PRETEST_PRAKOM_008::[html]Prinsip utama yang harus dipegang dalam penyusunan Strategi TI adalah \:{ | J37: =CONCATENATE(I37,I38,I39,I40,I41) -> ::PRETEST_PRAKOM_008::[html]Prinsip utama yang harus dipegang dalam penyusunan Strategi TI adalah \:{=[moodle]Keselarasan strategi TI dengan strategi bisnis organisasi ~[moodle]Pemerataan program kegiatan TI organisasi ~[moodle]Benar Semua ~[moodle]Salah Semua}
A38: Keselarasan strategi TI dengan strategi bisnis organisasi | B38: 1 | I38: =IF(B38=1,CONCATENATE("=",$G$7,A38," "),CONCATENATE("~",$G$7,A38," ")) -> =[moodle]Keselarasan strategi TI dengan strategi bisnis organisasi
A39: Pemerataan program kegiatan TI organisasi | B39: 0 | I39: =IF(B39=1,CONCATENATE("=",$G$7,A39," "),CONCATENATE("~",$G$7,A39," ")) -> ~[moodle]Pemerataan program kegiatan TI organisasi
A40: Benar Semua | B40: 0 | I40: =IF(B40=1,CONCATENATE("=",$G$7,A40," "),CONCATENATE("~",$G$7,A40," ")) -> ~[moodle]Benar Semua
...

Sheet HASIL SAVE AS TXT
A1: =Sheet1!$D$1 -> //PRAKOMAHLI_PRETEST
A3: =Sheet1!J2 -> ::PRETEST_PRAKOM_001::[html]Menurut Mayer, multimedia akan lebih maksimal jika menggunakan gabungan dari grafik dan narasi, dibandingkan dengan hanya penggunaan grafik saja atau narasi saja. Prinsip ini disebut \:{=[moodle]Redundansi ~[moodle]Kedekatan sementara ~[moodle]Penandanaan ~[moodle]Koherensi}
A5: =Sheet1!$D$1 -> //PRAKOMAHLI_PRETEST
A7: =Sheet1!J7 -> ::PRETEST_PRAKOM_002::[html]Peta tematik disebut juga dengan \:{~[moodle]Peta Umum =[moodle]Peta Khusus ~[moodle]Peta Topografi ~[moodle]Peta Dunia}
A9: =Sheet1!$D$1 -> //PRAKOMAHLI_PRETEST
A11: =Sheet1!J12 -> ::PRETEST_PRAKOM_003::[html]Konten yang merupakan kombinasi dari teks, suara, gambar, animasi, dan video yang dimanipulasi secara digital disebut \:{~[moodle]Adsense ~[moodle]Multilevel =[moodle]Multimedia ~[moodle]Flowchart}
A13: =Sheet1!$D$1 -> //PRAKOMAHLI_PRETEST
A15: =Sheet1!J17 -> =[moodle]Pengujian aplikasi yang dilakukan oleh pengguna menggunakan perangkat masing-masing disebut juga dengan ~[moodle]Integration Test ~[moodle]Destructive Test ~[moodle]Latency Test}
A17: =Sheet1!$D$1 -> //PRAKOMAHLI_PRETEST
A19: =Sheet1!J22 -> ::PRETEST_PRAKOM_005::[html]Keseluruhan inisiatif TI yang terdiri dari visi, misi, tujuan, prinsip, dan taktik yang berkaitan dengan pemanfaatan TI dalam organisasi tertuang di dalam \:{~[moodle]Kebijakan TI =[moodle]Strategi TI ~[moodle]Tata Kelola TI ~[moodle]Roadmap TI}
A21: =Sheet1!$D$1 -> //PRAKOMAHLI_PRETEST
A23: =Sheet1!J27 -> ::PRETEST_PRAKOM_006::[html]Suatu strategi yang spesifik untuk melaksanakan suatu rencana TI yang telah disusun agar dapat berjalan dan diimplementasikan sesuai dengan target yang diinginkan dengan menggunakan sumber daya seefektif dan seefisien mungkin \:{~[moodle]Strategi TI ~[moodle]Strategi Layanan TI ~[moodle]Strategi Pembiayaan TI =[moodle]Strategi Operasional TI}
A25: =Sheet1!$D$1 -> //PRAKOMAHLI_PRETEST
A27: =Sheet1!J32 -> ::PRETEST_PRAKOM_007::[html]Berikut ini yang bukan manfaat yang bisa didapatkan dari pengembangan Enterprise Architecture adalah \:{~[moodle]Mempunyai portofolio aplikasi dan teknologi yang dapat digunakan untuk pengelolaan TIK ~[moodle]Dapat dijadikan dasar pengembangan manajemen risiko =[moodle]Mempunyai informasi kebutuhan pengguna untuk dasar pengembangan aplikasi ~[moodle]Dasar perencanaan strategi dan pengambilan kebijakan}
A29: =Sheet1!$D$1 -> //PRAKOMAHLI_PRETEST
A31: =Sheet1!J37 -> ::PRETEST_PRAKOM_008::[html]Prinsip utama yang harus dipegang dalam penyusunan Strategi TI adalah \:{=[moodle]Keselarasan strategi TI dengan strategi bisnis organisasi ~[moodle]Pemerataan program kegiatan TI organisasi ~[moodle]Benar Semua ~[moodle]Salah Semua}
A33: =Sheet1!$D$1 -> //PRAKOMAHLI_PRETEST
A35: =Sheet1!J42 -> ::PRETEST_PRAKOM_009::[html]Model yang digunakan untuk mengukur tingkat kematangan keselarasan bisnis dan TI adalah \:{=[moodle]Strategic Alignment Maturity Model (SAMM) ~[moodle]Technology Acceptance Model (TAM) ~[moodle]Architecture Development Method (ADM) ~[moodle]Capability Maturity Model Integration (CMMI)}
A37: =Sheet1!$D$1 -> //PRAKOMAHLI_PRETEST
A39: =Sheet1!J47 -> ::PRETEST_PRAKOM_010::[html]Apakah yang dimaksud dengan spesifikasi teknis? \:{~[moodle]syarat-syarat barang/jasa yang sedang popular ~[moodle]ketentuan tenknis barang yang dijual di pasaran ~[moodle]rincian fitur barang/jasa yang ditawarkan =[moodle]Deskripsi harga menurut jenis barang/jasa}
A41: =Sheet1!$D$1 -> //PRAKOMAHLI_PRETEST
A43: =Sheet1!J52 -> ::PRETEST_PRAKOM_011::[html]Untuk dapat melakukan komunikasi menggunakan VOIP dibutuhkan beberapa komponen pendukung. Ada beberapa komponen pendukung yang harus ada dalam VOIP salah satunya adalah \:{~[moodle]Sender =[moodle]Protocol ~[moodle]Data ~[moodle]Server}
A45: =Sheet1!$D$1 -> //PRAKOMAHLI_PRETEST
A47: =Sheet1!J57 -> ::PRETEST_PRAKOM_012::[html]Bekerja menggunakan algoritma tertentu untuk membantu dalam memecah, mengurutkan, mengkompresi, dan merakit ulang audio data yang ditransmisikan adalah \:{~[moodle]Softphone ~[moodle]VoIP server =[moodle]Proses codec ~[moodle]Proses codec}
A49: =Sheet1!$D$1 -> //PRAKOMAHLI_PRETEST
A51: =Sheet1!J62 -> ::PRETEST_PRAKOM_013::[html]Sebelum tahap penyerahan, infrastruktur TI hasil pengadaan harus diperiksa kesesuaiannya dengan \:{=[moodle]Spesifikasi teknis ~[moodle]Brosur ~[moodle]Penawaran harga ~[moodle]spesifikasi pengguna}
A53: =Sheet1!$D$1 -> //PRAKOMAHLI_PRETEST
A55: =Sheet1!J67 -> ::PRETEST_PRAKOM_014::[html]Sebutkan proses-proses yang di cakup service strategy pada ITIL! \:{=[moodle]Service Portfolio Management, Financial Management, Demand Management ~[moodle]Service Level Management, Supplier Management, CApacity Management ~[moodle]Availibility Management, IT Service Continuity Management, Capacity Management ~[moodle]Information Security Management}
A57: =Sheet1!$D$1 -> //PRAKOMAHLI_PRETEST
A59: =Sheet1!J72 -> ::PRETEST_PRAKOM_015::[html]Fokus pada service desk merupakan bagian dari service mangement dan ini juga dipersyaratkan di dalam pengelolaan ISO ITSM. \:{~[moodle]2000 =[moodle]20000 ~[moodle]5000 ~[moodle]50000}
A61: =Sheet1!$D$1 -> //PRAKOMAHLI_PRETEST
A63: =Sheet1!J77 -> ::PRETEST_PRAKOM_016::[html]Proses yang berhubungan dengan pengelolaan perubahan infrastruktur atau aspek TI lainnya adalah \:{~[moodle]Change Management ~[moodle]Incident Management =[moodle]Service Request Management ~[moodle]Problem Management}
A65: =Sheet1!$D$1 -> //PRAKOMAHLI_PRETEST
A67: =Sheet1!J82 -> ::PRETEST_PRAKOM_017::[html]Berikut ini yang bukan merupakan proses manajemen risiko TI yaitu \:{~[moodle]Komunikasi dan konsultasi ~[moodle]Penilaian risiko TI ~[moodle]Pemantauan dan reviu =[moodle]Kepemimpinan dan komitmen}
A69: =Sheet1!$D$1 -> //PRAKOMAHLI_PRETEST
A71: =Sheet1!J87 -> ::PRETEST_PRAKOM_018::[html]Informasi yang harus didapatkan saat proses identifikasi risiko TI yaitu, kecuali \:{~[moodle]Jenis risiko TI ~[moodle]Penyebab risiko TI =[moodle]Level risiko TI ~[moodle]Kategori risiko TI}
A73: =Sheet1!$D$1 -> //PRAKOMAHLI_PRETEST
A75: =Sheet1!J92 -> ::PRETEST_PRAKOM_019::[html]Cara menentukan besaran nilai risiko TI pada matrik analisis risiko TI yaitu \:{~[moodle]Angka berurutan dari 1 sampai dengan hasil perkalian antara jumlah level kemungkinan dan jumlah level dampak ~[moodle]Angka hasil dari perkalian antara level kemungkinan dan level dampak =[moodle]Benar Semua ~[moodle]Salah semua}
A77: =Sheet1!$D$1 -> //PRAKOMAHLI_PRETEST
A79: =Sheet1!J97 -> ::PRETEST_PRAKOM_020::[html]Nilai acuan yang digunakan sebagai ambang batas minimum terhadap besaran risiko TI yang harus ditangani merupakan pengertian dari … \:{~[moodle]Residual risiko ~[moodle]Kriteria risiko ~[moodle]Selera risiko =[moodle]Level risiko}
...

Sheet Sheet2
A1: Yang bukan merupakan karakteristik dari GSBPM adalah: | B1: Alur sub-proses tidak harus berurutan dan iterasi tidak dimungkinkan | C1: Tidak bersifat linier | D1: Alur sub-proses tidak harus berurutan dan dimungkinkan adanya iterasi | E1: Merupakan sebuah matriks sehingga terdapat banyak kemungkinan urutan sub-proses | G1: Yang bukan merupakan karakteristik dari GSBPM adalah:
A2: Pengertian statistik sektoral adalah: | B2: Statistik yang pemanfaatannya ditujukan untuk memenuhi kebutuhan pembangunan sektor tertentu dalam rangka pemenuhan kebutuhan data untuk perencanaan dan evaluasi pembangunan. | C2: Statistik yang pemanfaatannya ditujukan untuk memenuhi kebutuhan instansi tertentu dalam rangka penyelenggaraan tugas-tugas pemerintahan dan pembangunan yang merupakan tugas pokok instansi yang bersangkutan serta statistik yang diselenggarakan oleh akademisi. | D2: Statistik yang pemanfaatannya ditujukan untuk memenuhi kebutuhan masyarakat tertentu dalam rangka pemenuhan kebutuhan data dalam perencanaan dan evaluasi program kerja sesuai sektor masing-masing. | E2: Statistik yang pemanfaatannya ditujukan untuk memenuhi kebutuhan instansi tertentu dalam rangka penyelenggaraan tugas-tugas pemerintahan dan pembangunan yang merupakan tugas pokok instansi yang bersangkutan. | G2: Alur sub-proses tidak harus berurutan dan iterasi tidak dimungkinkan
A3: Salah satu mekanisme penyampaian rencana penyelenggaraan kegiatan statistik sektoral diatur sebagai berikut | B3: Apabila wilayah penyelenggaraan kegiatan statistik hanya mencakup satu kabupaten/kota, maka pemberitahuan rencana penyelenggaraan kegiatan statistik disampaikan kepada Kepala BPS Kabupaten/Kota dan BPS Provinsi di wilayah yang bersangkutan | C3: Apabila wilayah penyelenggaraan kegiatan statistik hanya mencakup satu provinsi atau beberapa kabupaten/kota dalam satu provinsi, maka pemberitahuan rencana penyelenggaraan kegiatan statistik disampaikan kepada Kepala BPS Provinsi dan Kepala BPS Kabupaten/Kota di wilayah yang bersangkutan | D3: Apabila wilayah penyelenggaraan kegiatan statistik mencakup lebih dari satu provinsi, maka pemberitahuan rencana penyelenggaraan kegiatan statistik disampaikan kepada seluruh Kepala BPS Provinsi tempat penyelenggaraan kegiatan tersebut | E3: Apabila kegiatan statistik diselenggarakan oleh instansi pemerintah pusat di daerah tertentu, pemberitahuan rencana kegiatan statistik disampaikan oleh K/L penyelenggara kepada Kepala BPS dengan tembusan kepada Kepala BPS di wilayah yang bersangkutan | G3: Tidak bersifat linier
A4: Dalam skema Satu Data Indonesia, permasalahan data yang dihadapi dapat dibahas bersama dalam suatu wadah komunikasi dan koordinasi antar Instansi Pusat dan /atau Instansi Daerah yang disebut dengan …. | B4: Sekretariat Satu Data Indonesia | C4: Walidata | D4: Forum Satu Data Indonesia | E4: Workshop Data | G4: Alur sub-proses tidak harus berurutan dan dimungkinkan adanya iterasi
A5: Penguatan Sistem Statistik Nasional (SSN) dilakukan dengan melalui penyelenggaraan statistik berikut, kecuali... | B5: Statistik Dasar | C5: Statistik Sektoral | D5: Statistik Kelembagaan | E5: Statistik Khusus | G5: Merupakan sebuah matriks sehingga terdapat banyak kemungkinan urutan sub-proses
A6: Landasan hukum yang menyebutkan tentang Satu Data Indonesia adalah.... | B6: Undang-Undang Nomor 16 Tahun 1997 | C6: Peraturan Pemerintah Nomor 51 Tahun 1999 | D6: Peraturan Presiden Nomor 39 Tahun 2019 | E6: Peraturan Badan Pusat Statistik Nomor 10 Tahun 2021 | G6: Pengertian statistik sektoral adalah:
A7: Evaluasi Penyelenggaraan Statistik Sektoral merupakan proses penilaian terhadap pelaksanaan penyelenggaraan statistik sektoral di Instansi Pusat dan Pemerintah Daerah untuk menghasilkan nilai IPS. Apa kepanjangan dari IPS? | B7: Indeks Pemantauan Statistik | C7: Indeks Penyelenggaraan Statistik | D7: Indeks Pembangunan Statistik | E7: Indeks Pelaksanaan Statistik | G7: Statistik yang pemanfaatannya ditujukan untuk memenuhi kebutuhan pembangunan sektor tertentu dalam rangka pemenuhan kebutuhan data untuk perencanaan dan evaluasi pembangunan.
A8: Berikut adalah tahap - tahap dari seluruh tahapan evaluasi penyelenggaraan statistik sektoral, kecuali | B8: Tahap Persiapan | C8: Tahap Pelaksanaan | D8: Tahap Pemantauan | E8: Tahap Pelaporan | G8: Statistik yang pemanfaatannya ditujukan untuk memenuhi kebutuhan instansi tertentu dalam rangka penyelenggaraan tugas-tugas pemerintahan dan pembangunan yang merupakan tugas pokok instansi yang bersangkutan serta statistik yang diselenggarakan oleh akademisi.
A9: Berdasarkan struktur penilaian IPS, domain Prinsip SDI terdiri dari 4 Aspek. Aspek berikut yang merupakan aspek pada domain Prinsip SDI adalah | B9: Profesionalitas | C9: Pengelolaan Standar Data Statistik | D9: Relevansi | E9: Kode Referensi dan/atau Data Induk | G9: Statistik yang pemanfaatannya ditujukan untuk memenuhi kebutuhan masyarakat tertentu dalam rangka pemenuhan kebutuhan data dalam perencanaan dan evaluasi program kerja sesuai sektor masing-masing.
A10: Informasi spesifik dari aspek pelaksanaan Penyelenggaraan Statistik Sektoral yang dinilai disebut | B10: Domain | C10: Aspek | D10: Indikator | E10: Indeks | G10: Statistik yang pemanfaatannya ditujukan untuk memenuhi kebutuhan instansi tertentu dalam rangka penyelenggaraan tugas-tugas pemerintahan dan pembangunan yang merupakan tugas pokok instansi yang bersangkutan.
A11: Berikut yang bukan ciri-ciri tingkat kematangan RINTISAN kecuali | B11: Pelaksanaan masih bersifat ad hoc | C11: Proses tata kelola dijalankan dengan dasar-dasar manajemen | D11: Semua unit organisasi sama dalam pelaksanaan proses tata kelola | E11: Kinerja penyelenggaraan statistik sektoral dapat diukur melalui kegiatan reviu dan evaluasi pada setiap proses | G11: Salah satu mekanisme penyampaian rencana penyelenggaraan kegiatan statistik sektoral diatur sebagai berikut
A12: Berapa jumlah aspek yang digunakan dalam pengukuran IPS dalam rangka Evaluasi Penyelenggaraan Statistik Sektoral? | B12: 16 | C12: 17 | D12: 18 | E12: 19 | G12: Apabila wilayah penyelenggaraan kegiatan statistik hanya mencakup satu kabupaten/kota, maka pemberitahuan rencana penyelenggaraan kegiatan statistik disampaikan kepada Kepala BPS Kabupaten/Kota dan BPS Provinsi di wilayah yang bersangkutan
A13: Berikut adalah tugas dari tim penilai badan, kecuali | B13: Melakukan penilaian dokumen, penilaian interviu dan visitasi | C13: Menyusun laporan Tim Penilai Badan | D13: Memberi catatan atas penilaian, rekomendasi atau saran perbaikan | E13: Melakukan entri data dan bukti dukung ke aplikasi | G13: Apabila wilayah penyelenggaraan kegiatan statistik hanya mencakup satu provinsi atau beberapa kabupaten/kota dalam satu provinsi, maka pemberitahuan rencana penyelenggaraan kegiatan statistik disampaikan kepada Kepala BPS Provinsi dan Kepala BPS Kabupaten/Kota di wilayah yang bersangkutan
A14: Tim Penilai Badan ditetapkan oleh... | B14: Koordinator Tim Penilai Internal | C14: Kepala Instansi/Kepala Pemerintah Daerah | D14: Kepala Badan | E14: Tim Penjaminan Kualitas | G14: Apabila wilayah penyelenggaraan kegiatan statistik mencakup lebih dari satu provinsi, maka pemberitahuan rencana penyelenggaraan kegiatan statistik disampaikan kepada seluruh Kepala BPS Provinsi tempat penyelenggaraan kegiatan tersebut
A15: Berapa nilai tingkatan kriteria jika suatu unit kerja pada Instansi Pusat atau Pemerintah Daerah telah berada pada tahap Usulan SDS telah dilakukan harmonisasi oleh Walidata dan ditetapkan untuk semua produsen data, atau SDS yang ditetapkan oleh BPS digunakan oleh semua produsen data. | B15: 1 | C15: 2 | D15: 3 | E15: 4 | G15: Apabila kegiatan statistik diselenggarakan oleh instansi pemerintah pusat di daerah tertentu, pemberitahuan rencana kegiatan statistik disampaikan oleh K/L penyelenggara kepada Kepala BPS dengan tembusan kepada Kepala BPS di wilayah yang bersangkutan
A16: Berapa nilai tingkatan kriteria jika suatu unit kerja pada Instansi Pusat atau Pemerintah Daerah telah berada pada tahap metadata telah diterapkan oleh setiap Produsen Data dengan kaidah yang berlaku untuk unit produsen datanya sendiri. | B16: 1 | C16: 2 | D16: 3 | E16: 4 | G16: Dalam skema Satu Data Indonesia, permasalahan data yang dihadapi dapat dibahas bersama dalam suatu wadah komunikasi dan koordinasi antar Instansi Pusat dan /atau Instansi Daerah yang disebut dengan ….
A17: Setiap data yang dihasilkan harus memiliki metadata. Berikut ini yang masing-masing berperan menyusun metadata, memeriksa metadata, dan menerima laporan metadata statistik adalah ... | B17: Instansi Pusat/Daerah, Walidata, Koordinator Forum Data | C17: Walidata, Koordinator Forum Data, BPS | D17: Produsen Data, Walidata, BPS | E17: Instansi Pusat/Daerah, Produsen Data, Walidata | G17: Sekretariat Satu Data Indonesia
A18: Berapa jumlah indikator dalam aspek Interoperabilitas pada domain Prinsip SDI yang digunakan dalam pengukuran IPS dalam rangka Evaluasi Penyelenggaraan Statistik Sektoral? | B18: 1 | C18: 2 | D18: 3 | E18: 4 | G18: Walidata
A19: Sebutkan nama indikator dalam aspek Relevansi dalam pengukuran IPS? | B19: Tingkat Kematangan Proses Identifikasi Kebutuhan Data | C19: Tingkat Kematangan Penilaian Akurasi Data | D19: Tingkat Kematangan Evaluasi Ketepatan Waktu Diseminasi | E19: Tingkat Kematangan Ketersediaan Data untuk Pengguna Data | G19: Forum Satu Data Indonesia
A20: Berapa jumlah indikator dalam aspek Akurasi pada domain Kualitas Data yang digunakan dalam pengukuran IPS dalam rangka Evaluasi Penyelenggaraan Statistik Sektoral? | B20: 1 | C20: 2 | D20: 3 | E20: 4 | G20: Workshop Data
A21: Berapa jumlah indikator dalam aspek Aktualitas & Ketepatan Waktu pada domain Kualitas Data yang digunakan dalam pengukuran IPS dalam rangka Evaluasi Penyelenggaraan Statistik Sektoral? | B21: 1 | C21: 2 | D21: 3 | E21: 4 | G21: Penguatan Sistem Statistik Nasional (SSN) dilakukan dengan melalui penyelenggaraan statistik berikut, kecuali...
A22: Suatu unit kerja menyusun Indeks Kepuasan Masyarakat dan membuat gap antara harapan dengan kepuasan pengguna terhadap layanan yang diterima. Aktivitas tersebut merupakan contoh penerapan indikator apa dari domain 3 (proses bisnis statistik) dan aspek 2 (perencanaan)? | B22: Indikator 3 (Tingkat Kematangan Penyiapan Instrumen) | C22: Indikator 1 (Tingkat Kematangan Pendefinisian Kebutuhan Statistik) | D22: Indikator 2 (Tingkat Kematangan Desain Statistik) | E22: Indikator 1(Tingkat Kematangan Proses Pengumpulan Data / Akuisisi data) | G22: Statistik Dasar
A23: Tahapan kegiatan mencari data/informasi di lapangan atau akuisisi dari sumber lain yang dilakukan pada proses stastistik adalah merupakan definisi dari indikator ke-1 pada domain proses bisnis dan aspek.... | B23: Perencanaan data | C23: pemeriksaan data | D23: pengumpulan data | E23: penyebarluasan data | G23: Statistik Sektoral
A24: Penjaminan Netralitas dan Obyektivitas terhadap Penggunaan Sumber Data dan Metodologi bertujuan untuk | B24: Menetapkan hak pengguna data dalam memanfaatkan data statistik. | C24: Memberikan informasi kualitas data kepada pengguna agar dapat memanfaat secara optimal. | D24: Menjamin data/informasi yang dihasilkan objektif sesuai dengan keilmuan statistik, dengan rujukan atau standar nasional dan internasional, serta mempertimbangkan efisiensi dan efektivitas. | E24: Menjamin kerahasiaan data individu agar tidak disalahgunakan oleh pihak yang tidak bertanggungjawab | G24: Statistik Kelembagaan
A25: Pengukuran Indikator "Tingkat Kematangan Penggunaan Data Statistik Sektoral untuk Perencanaan, Monitoring, dan Evaluasi, dan / atau Penyusunan Kebijakan" bertujuan untuk | B25: Mengidentifikasi proses pemahaman pengguna data terhadap data yang dihasilkan produsen data | C25: Mengidentifikasi apakah Instansi Pusat dan Pemerintah Daerah terkait telah memanfaatkan berbagai data statistik sektoral yang tersedia di internal/eksternal Instansi Pusat dan Pemerintah Daerah untuk mendukung pembangunan nasional serta jalannya pemerintahan, khususnya dalam aspek perencanaan, monitoring, dan evaluasi di instansi yang bersangkutan. | D25: Menunjukkan bagaimana statistik dibutuhkan oleh berbagai pihak baik internal maupun eksternal. | E25: Memastikan bahwa data/informasi yang didiseminasikan dapat digabungkan dan digunakan secara bersama, termasuk data dari berbagai sumber yang berbeda. | G25: Statistik Khusus
G26: Landasan hukum yang menyebutkan tentang Satu Data Indonesia adalah....
G27: Undang-Undang Nomor 16 Tahun 1997
G28: Peraturan Pemerintah Nomor 51 Tahun 1999
G29: Peraturan Presiden Nomor 39 Tahun 2019
G30: Peraturan Badan Pusat Statistik Nomor 10 Tahun 2021
G31: Evaluasi Penyelenggaraan Statistik Sektoral merupakan proses penilaian terhadap pelaksanaan penyelenggaraan statistik sektoral di Instansi Pusat dan Pemerintah Daerah untuk menghasilkan nilai IPS. Apa kepanjangan dari IPS?
G32: Indeks Pemantauan Statistik
G33: Indeks Penyelenggaraan Statistik
G34: Indeks Pembangunan Statistik
G35: Indeks Pelaksanaan Statistik
G36: Berikut adalah tahap - tahap dari seluruh tahapan evaluasi penyelenggaraan statistik sektoral, kecuali
G37: Tahap Persiapan
... G56: Berapa jumlah aspek yang digunakan dalam pengukuran IPS dalam rangka Evaluasi Penyelenggaraan Statistik Sektoral?
G57: 16
G58: 17
...
